<sdf version='1.6'>
  <model name='if750a_reverse_arm_heavy_base'>
    <link name='base_link'>
      <pose>0 0 0 0 -0 0</pose>
      <inertial>
        <pose>0 0 0.25 0 -0 0</pose>
        <mass>9</mass>
        <inertia>
          <ixx>0.2085378</ixx>
          <ixy>0</ixy>
          <ixz>0</ixz>
          <iyy>0.2753574</iyy>
          <iyz>0</iyz>
          <izz>0.5862</izz>
        </inertia>
      </inertial>
      <collision name='base_link_inertia_collision_left'>
        <pose>0 0.18 -0.08 0 -0 0</pose>
        <geometry>
          <box>
            <size>0.35 0.1 0.05</size>
          </box>
        </geometry>
        <surface>
          <contact>
            <ode>
              <min_depth>0.001</min_depth>
              <max_vel>0</max_vel>
            </ode>
          </contact>
          <friction>
            <ode/>
          </friction>
        </surface>
      </collision>
      <collision name='base_link_inertia_collision_right'>
        <pose>0 -0.18 -0.08 0 -0 0</pose>
        <geometry>
          <box>
            <size>0.35 0.1 0.05</size>
          </box>
        </geometry>
        <surface>
          <contact>
            <ode>
              <min_depth>0.001</min_depth>
              <max_vel>0</max_vel>
            </ode>
          </contact>
          <friction>
            <ode/>
          </friction>
        </surface>
      </collision>
      <visual name='base_link_inertia_visual'>
        <pose>0 0 0 1.570796 -0 1.57079632679489661923</pose>
        <geometry>
          <mesh>
            <scale>0.001 0.001 0.001</scale>
            <uri>model://if750a_reverse_arm_heavy_base/meshes/if750a_long_leg.stl</uri>
          </mesh>
        </geometry>
        <material>
          <script>
            <name>Gazebo/DarkGrey</name>
            <uri>file://media/materials/scripts/gazebo.material</uri>
          </script>
        </material>
      </visual>
      <gravity>1</gravity>
      <velocity_decay/>
      <self_collide>0</self_collide>
    </link>
    <link name='/imu_link'>
      <pose>0 0 0 0 -0 0</pose>
      <inertial>
        <pose>0 0 0 0 -0 0</pose>
        <mass>0.015</mass>
        <inertia>
          <ixx>1e-05</ixx>
          <ixy>0</ixy>
          <ixz>0</ixz>
          <iyy>1e-05</iyy>
          <iyz>0</iyz>
          <izz>1e-05</izz>
        </inertia>
      </inertial>
    </link>
    <joint name='/imu_joint' type='revolute'>
      <child>/imu_link</child>
      <parent>base_link</parent>
      <axis>
        <xyz>1 0 0</xyz>
        <limit>
          <lower>0</lower>
          <upper>0</upper>
          <effort>0</effort>
          <velocity>0</velocity>
        </limit>
        <dynamics>
          <spring_reference>0</spring_reference>
          <spring_stiffness>0</spring_stiffness>
        </dynamics>
        <use_parent_model_frame>1</use_parent_model_frame>
      </axis>
    </joint>
    <link name='rotor_0'>
      <pose>0.265 -0.265 0.35 0 -0 0</pose>
      <inertial>
        <pose>0 0 0 0 -0 0</pose>
        <mass>0.005</mass>
        <inertia>
          <ixx>9.75e-07</ixx>
          <ixy>0</ixy>
          <ixz>0</ixz>
          <iyy>0.000273104</iyy>
          <iyz>0</iyz>
          <izz>0.000274004</izz>
        </inertia>
      </inertial>
      <collision name='rotor_0_collision'>
        <pose>0 0 0 0 -0 0</pose>
        <geometry>
          <cylinder>
            <length>0.005</length>
            <radius>0.128</radius>
          </cylinder>
        </geometry>
        <surface>
          <contact>
            <ode/>
          </contact>
          <friction>
            <ode/>
          </friction>
        </surface>
      </collision>
      <visual name='rotor_0_visual'>
        <pose>0 0 0 0 -0 0</pose>
        <geometry>
          <mesh>
            <scale>1 1 1</scale>
            <uri>model://iris/meshes/iris_prop_ccw.dae</uri>
          </mesh>
        </geometry>
        <material>
          <script>
            <name>Gazebo/Blue</name>
            <uri>file://media/materials/scripts/gazebo.material</uri>
          </script>
        </material>
      </visual>
      <gravity>1</gravity>
      <velocity_decay/>
      <self_collide>0</self_collide>
    </link>
    <joint name='rotor_0_joint' type='revolute'>
      <child>rotor_0</child>
      <parent>base_link</parent>
      <axis>
        <xyz>0 0 1</xyz>
        <limit>
          <lower>-1e+16</lower>
          <upper>1e+16</upper>
        </limit>
        <dynamics>
          <spring_reference>0</spring_reference>
          <spring_stiffness>0</spring_stiffness>
        </dynamics>
        <use_parent_model_frame>1</use_parent_model_frame>
      </axis>
    </joint>
    <link name='rotor_1'>
      <pose>-0.265 0.265 0.35 0 -0 0</pose>
      <inertial>
        <pose>0 0 0 0 -0 0</pose>
        <mass>0.005</mass>
        <inertia>
          <ixx>9.75e-07</ixx>
          <ixy>0</ixy>
          <ixz>0</ixz>
          <iyy>0.000273104</iyy>
          <iyz>0</iyz>
          <izz>0.000274004</izz>
        </inertia>
      </inertial>
      <collision name='rotor_1_collision'>
        <pose>0 0 0 0 -0 0</pose>
        <geometry>
          <cylinder>
            <length>0.005</length>
            <radius>0.128</radius>
          </cylinder>
        </geometry>
        <surface>
          <contact>
            <ode/>
          </contact>
          <friction>
            <ode/>
          </friction>
        </surface>
      </collision>
      <visual name='rotor_1_visual'>
        <pose>0 0 0 0 -0 0</pose>
        <geometry>
          <mesh>
            <scale>1 1 1</scale>
            <uri>model://iris/meshes/iris_prop_ccw.dae</uri>
          </mesh>
        </geometry>
        <material>
          <script>
            <name>Gazebo/DarkGrey</name>
            <uri>file://media/materials/scripts/gazebo.material</uri>
          </script>
        </material>
      </visual>
      <gravity>1</gravity>
      <velocity_decay/>
      <self_collide>0</self_collide>
    </link>
    <joint name='rotor_1_joint' type='revolute'>
      <child>rotor_1</child>
      <parent>base_link</parent>
      <axis>
        <xyz>0 0 1</xyz>
        <limit>
          <lower>-1e+16</lower>
          <upper>1e+16</upper>
        </limit>
        <dynamics>
          <spring_reference>0</spring_reference>
          <spring_stiffness>0</spring_stiffness>
        </dynamics>
        <use_parent_model_frame>1</use_parent_model_frame>
      </axis>
    </joint>
    <link name='rotor_2'>
      <pose>0.265 0.265 0.35 0 -0 0</pose>
      <inertial>
        <pose>0 0 0 0 -0 0</pose>
        <mass>0.005</mass>
        <inertia>
          <ixx>9.75e-07</ixx>
          <ixy>0</ixy>
          <ixz>0</ixz>
          <iyy>0.000273104</iyy>
          <iyz>0</iyz>
          <izz>0.000274004</izz>
        </inertia>
      </inertial>
      <collision name='rotor_2_collision'>
        <pose>0 0 0 0 -0 0</pose>
        <geometry>
          <cylinder>
            <length>0.005</length>
            <radius>0.128</radius>
          </cylinder>
        </geometry>
        <surface>
          <contact>
            <ode/>
          </contact>
          <friction>
            <ode/>
          </friction>
        </surface>
      </collision>
      <visual name='rotor_2_visual'>
        <pose>0 0 0 0 -0 0</pose>
        <geometry>
          <mesh>
            <scale>1 1 1</scale>
            <uri>model://iris/meshes/iris_prop_cw.dae</uri>
          </mesh>
        </geometry>
        <material>
          <script>
            <name>Gazebo/Blue</name>
            <uri>file://media/materials/scripts/gazebo.material</uri>
          </script>
        </material>
      </visual>
      <gravity>1</gravity>
      <velocity_decay/>
      <self_collide>0</self_collide>
    </link>
    <joint name='rotor_2_joint' type='revolute'>
      <child>rotor_2</child>
      <parent>base_link</parent>
      <axis>
        <xyz>0 0 1</xyz>
        <limit>
          <lower>-1e+16</lower>
          <upper>1e+16</upper>
        </limit>
        <dynamics>
          <spring_reference>0</spring_reference>
          <spring_stiffness>0</spring_stiffness>
        </dynamics>
        <use_parent_model_frame>1</use_parent_model_frame>
      </axis>
    </joint>
    <link name='rotor_3'>
      <pose>-0.265 -0.265 0.35 0 -0 0</pose>
      <inertial>
        <pose>0 0 0 0 -0 0</pose>
        <mass>0.005</mass>
        <inertia>
          <ixx>9.75e-07</ixx>
          <ixy>0</ixy>
          <ixz>0</ixz>
          <iyy>0.000273104</iyy>
          <iyz>0</iyz>
          <izz>0.000274004</izz>
        </inertia>
      </inertial>
      <collision name='rotor_3_collision'>
        <pose>0 0 0 0 -0 0</pose>
        <geometry>
          <cylinder>
            <length>0.005</length>
            <radius>0.128</radius>
          </cylinder>
        </geometry>
        <surface>
          <contact>
            <ode/>
          </contact>
          <friction>
            <ode/>
          </friction>
        </surface>
      </collision>
      <visual name='rotor_3_visual'>
        <pose>0 0 0 0 -0 0</pose>
        <geometry>
          <mesh>
            <scale>1 1 1</scale>
            <uri>model://iris/meshes/iris_prop_cw.dae</uri>
          </mesh>
        </geometry>
        <material>
          <script>
            <name>Gazebo/DarkGrey</name>
            <uri>file://media/materials/scripts/gazebo.material</uri>
          </script>
        </material>
      </visual>
      <gravity>1</gravity>
      <velocity_decay/>
      <self_collide>0</self_collide>
    </link>
    <joint name='rotor_3_joint' type='revolute'>
      <child>rotor_3</child>
      <parent>base_link</parent>
      <axis>
        <xyz>0 0 1</xyz>
        <limit>
          <lower>-1e+16</lower>
          <upper>1e+16</upper>
        </limit>
        <dynamics>
          <spring_reference>0</spring_reference>
          <spring_stiffness>0</spring_stiffness>
        </dynamics>
        <use_parent_model_frame>1</use_parent_model_frame>
      </axis>
    </joint>
    <plugin name='rosbag' filename='libgazebo_multirotor_base_plugin.so'>
      <robotNamespace/>
      <linkName>base_link</linkName>
      <rotorVelocitySlowdownSim>10</rotorVelocitySlowdownSim>
    </plugin>
    <include>
      <uri>model://gps</uri>
      <pose>-0.01 0.173 0.47 0 0 0</pose>
      <name>gps0</name>
    </include>
    <joint name='gps0_joint' type='fixed'>
      <child>gps0::link</child>
      <parent>base_link</parent>
    </joint>
    <include>
      <uri>model://gps</uri>
      <pose>0.001 -0.173 0.47 0 0 0</pose>
      <name>gps1</name>
    </include>
    <joint name='gps1_joint' type='fixed'>
      <child>gps1::link</child>
      <parent>base_link</parent>
    </joint>
    <plugin name='front_right_motor_model' filename='libgazebo_motor_model.so'>
      <robotNamespace/>
      <jointName>rotor_0_joint</jointName>
      <linkName>rotor_0</linkName>
      <turningDirection>ccw</turningDirection>
      <timeConstantUp>0.0125</timeConstantUp>
      <timeConstantDown>0.025</timeConstantDown>
      <maxRotVelocity>1100</maxRotVelocity>
      <motorConstant>5.984e-5</motorConstant>
      <momentConstant>0.01</momentConstant>
      <commandSubTopic>/gazebo/command/motor_speed</commandSubTopic>
      <motorNumber>0</motorNumber>
      <rotorDragCoefficient>0.000106428</rotorDragCoefficient>
      <rollingMomentCoefficient>1e-06</rollingMomentCoefficient>
      <motorSpeedPubTopic>/motor_speed/0</motorSpeedPubTopic>
      <rotorVelocitySlowdownSim>10</rotorVelocitySlowdownSim>
    </plugin>
    <plugin name='back_left_motor_model' filename='libgazebo_motor_model.so'>
      <robotNamespace/>
      <jointName>rotor_1_joint</jointName>
      <linkName>rotor_1</linkName>
      <turningDirection>ccw</turningDirection>
      <timeConstantUp>0.0125</timeConstantUp>
      <timeConstantDown>0.025</timeConstantDown>
      <maxRotVelocity>1100</maxRotVelocity>
      <motorConstant>5.984e-5</motorConstant>
      <momentConstant>0.01</momentConstant>
      <commandSubTopic>/gazebo/command/motor_speed</commandSubTopic>
      <motorNumber>1</motorNumber>
      <rotorDragCoefficient>0.000106428</rotorDragCoefficient>
      <rollingMomentCoefficient>1e-06</rollingMomentCoefficient>
      <motorSpeedPubTopic>/motor_speed/1</motorSpeedPubTopic>
      <rotorVelocitySlowdownSim>10</rotorVelocitySlowdownSim>
    </plugin>
    <plugin name='front_left_motor_model' filename='libgazebo_motor_model.so'>
      <robotNamespace/>
      <jointName>rotor_2_joint</jointName>
      <linkName>rotor_2</linkName>
      <turningDirection>cw</turningDirection>
      <timeConstantUp>0.0125</timeConstantUp>
      <timeConstantDown>0.025</timeConstantDown>
      <maxRotVelocity>1100</maxRotVelocity>
      <motorConstant>5.984e-5</motorConstant>
      <momentConstant>0.01</momentConstant>
      <commandSubTopic>/gazebo/command/motor_speed</commandSubTopic>
      <motorNumber>2</motorNumber>
      <rotorDragCoefficient>0.000106428</rotorDragCoefficient>
      <rollingMomentCoefficient>1e-06</rollingMomentCoefficient>
      <motorSpeedPubTopic>/motor_speed/2</motorSpeedPubTopic>
      <rotorVelocitySlowdownSim>10</rotorVelocitySlowdownSim>
    </plugin>
    <plugin name='back_right_motor_model' filename='libgazebo_motor_model.so'>
      <robotNamespace/>
      <jointName>rotor_3_joint</jointName>
      <linkName>rotor_3</linkName>
      <turningDirection>cw</turningDirection>
      <timeConstantUp>0.0125</timeConstantUp>
      <timeConstantDown>0.025</timeConstantDown>
      <maxRotVelocity>1100</maxRotVelocity>
      <motorConstant>5.984e-5</motorConstant>
      <momentConstant>0.01</momentConstant>
      <commandSubTopic>/gazebo/command/motor_speed</commandSubTopic>
      <motorNumber>3</motorNumber>
      <rotorDragCoefficient>0.000106428</rotorDragCoefficient>
      <rollingMomentCoefficient>1e-06</rollingMomentCoefficient>
      <motorSpeedPubTopic>/motor_speed/3</motorSpeedPubTopic>
      <rotorVelocitySlowdownSim>10</rotorVelocitySlowdownSim>
    </plugin>
    <plugin name='groundtruth_plugin' filename='libgazebo_groundtruth_plugin.so'>
      <robotNamespace/>
    </plugin>
    <plugin name='magnetometer_plugin' filename='libgazebo_magnetometer_plugin.so'>
      <robotNamespace/><pubRate>100</pubRate>
      <noiseDensity>0.0</noiseDensity>
      <randomWalk>0.0</randomWalk>
      <biasCorrelationTime>600</biasCorrelationTime>
      <magTopic>/mag</magTopic>
      <!-- <pubRate>100</pubRate>
      <noiseDensity>0.0004</noiseDensity>
      <randomWalk>6.4e-06</randomWalk>
      <biasCorrelationTime>600</biasCorrelationTime>
      <magTopic>/mag</magTopic> -->
    </plugin>
    <plugin name='barometer_plugin' filename='libgazebo_barometer_plugin.so'>
      <robotNamespace/>
      <pubRate>50</pubRate>
      <baroTopic>/baro</baroTopic>
    </plugin>
    <plugin name='parachute_plugin' filename='libgazebo_parachute_plugin.so'>
      <robotNamespace/>
      <commandSubTopic>/gazebo/command/motor_speed</commandSubTopic>
      <motorNumber>4</motorNumber>
    </plugin>
    <plugin name='mavlink_interface' filename='libgazebo_mavlink_interface.so'>
      <robotNamespace/>
      <imuSubTopic>/imu</imuSubTopic>
      <magSubTopic>/mag</magSubTopic>
      <baroSubTopic>/baro</baroSubTopic>
      <mavlink_addr>INADDR_ANY</mavlink_addr>
      <mavlink_udp_port>14560</mavlink_udp_port>
      <mavlink_tcp_port>4560</mavlink_tcp_port>
      <serialEnabled>false</serialEnabled>
      <serialDevice>/dev/ttyACM0</serialDevice>
      <baudRate>921600</baudRate>
      <qgc_addr>INADDR_ANY</qgc_addr>
      <qgc_udp_port>14550</qgc_udp_port>
      <hil_mode>false</hil_mode>
      <hil_state_level>false</hil_state_level>
      <enable_lockstep>true</enable_lockstep>
      <use_tcp>true</use_tcp>
      <send_vision_estimation>true</send_vision_estimation>
      <send_odometry>false</send_odometry>
      <motorSpeedCommandPubTopic>/gazebo/command/motor_speed</motorSpeedCommandPubTopic>
      <control_channels>
        <channel name='rotor1'>
          <input_index>0</input_index>
          <input_offset>0</input_offset>
          <input_scaling>1000</input_scaling>
          <zero_position_disarmed>0</zero_position_disarmed>
          <zero_position_armed>100</zero_position_armed>
          <joint_control_type>velocity</joint_control_type>
        </channel>
        <channel name='rotor2'>
          <input_index>1</input_index>
          <input_offset>0</input_offset>
          <input_scaling>1000</input_scaling>
          <zero_position_disarmed>0</zero_position_disarmed>
          <zero_position_armed>100</zero_position_armed>
          <joint_control_type>velocity</joint_control_type>
        </channel>
        <channel name='rotor3'>
          <input_index>2</input_index>
          <input_offset>0</input_offset>
          <input_scaling>1000</input_scaling>
          <zero_position_disarmed>0</zero_position_disarmed>
          <zero_position_armed>100</zero_position_armed>
          <joint_control_type>velocity</joint_control_type>
        </channel>
        <channel name='rotor4'>
          <input_index>3</input_index>
          <input_offset>0</input_offset>
          <input_scaling>1000</input_scaling>
          <zero_position_disarmed>0</zero_position_disarmed>
          <zero_position_armed>100</zero_position_armed>
          <joint_control_type>velocity</joint_control_type>
        </channel>
        <channel name='aux1'>
          <input_index>4</input_index>
          <input_offset>0</input_offset>
          <input_scaling>1000</input_scaling>
          <zero_position_disarmed>0</zero_position_disarmed>
          <zero_position_armed>100</zero_position_armed>
          <joint_control_type>velocity</joint_control_type>
        </channel>
      </control_channels>
    </plugin>
    <static>0</static>
    <plugin name='rotors_gazebo_imu_plugin' filename='libgazebo_imu_plugin.so'>
      <robotNamespace/>
      <linkName>/imu_link</linkName>
      <imuTopic>/imu</imuTopic>
      <gyroscopeNoiseDensity>0.0</gyroscopeNoiseDensity>
      <gyroscopeRandomWalk>0.0</gyroscopeRandomWalk>
      <gyroscopeBiasCorrelationTime>1000.0</gyroscopeBiasCorrelationTime>
      <gyroscopeTurnOnBiasSigma>0.0087</gyroscopeTurnOnBiasSigma>
      <accelerometerNoiseDensity>0.0</accelerometerNoiseDensity>
      <accelerometerRandomWalk>0.0</accelerometerRandomWalk>
      <accelerometerBiasCorrelationTime>300.0</accelerometerBiasCorrelationTime>
      <accelerometerTurnOnBiasSigma>0.196</accelerometerTurnOnBiasSigma>
      <!-- <gyroscopeNoiseDensity>0.0003394</gyroscopeNoiseDensity>
      <gyroscopeRandomWalk>3.8785e-05</gyroscopeRandomWalk>
      <gyroscopeBiasCorrelationTime>1000.0</gyroscopeBiasCorrelationTime>
      <gyroscopeTurnOnBiasSigma>0.0087</gyroscopeTurnOnBiasSigma>
      <accelerometerNoiseDensity>0.004</accelerometerNoiseDensity>
      <accelerometerRandomWalk>0.006</accelerometerRandomWalk>
      <accelerometerBiasCorrelationTime>300.0</accelerometerBiasCorrelationTime>
      <accelerometerTurnOnBiasSigma>0.196</accelerometerTurnOnBiasSigma> -->
    </plugin>

     <!-- add wx200 arm -->
    <joint name='widowx200_baselink_to_drone_baselink' type='fixed'>
      <child>wx200/base_link</child>
      <parent>base_link</parent>
    </joint>
    <link name='wx200/base_link'>
      <pose frame=''>0 0 0.23 -3.14 0 0</pose>
      <inertial>
        <pose frame=''>-0.038175 0.000648 0.019346 0 -0 1.5708</pose>
        <mass>0.540142</mass>
        <inertia>
          <ixx>0.002119</ixx>
          <ixy>-1.721e-05</ixy>
          <ixz>6.389e-07</ixz>
          <iyy>0.0006925</iyy>
          <iyz>4.612e-05</iyz>
          <izz>0.002528</izz>
        </inertia>
      </inertial>
      <collision name='wx200/base_link_collision'>
        <pose frame=''>0 0 0 0 -0 1.5708</pose>
        <geometry>
          <mesh>
            <scale>0.001 0.001 0.001</scale>
            <uri>/home/argrobotx/robotx-2022/catkin_ws/src/interbotix_arm/interbotix_ros_manipulators/interbotix_ros_xsarms/interbotix_xsarm_descriptions/meshes/wx200_meshes/wx200_1_baseg.stl</uri>
          </mesh>
        </geometry>
        <max_contacts>10</max_contacts>
      </collision>
      <visual name='wx200/base_link_visual'>
        <pose frame=''>0 0 0 0 -0 1.5708</pose>
        <geometry>
          <mesh>
            <scale>0.001 0.001 0.001</scale>
            <uri>/home/argrobotx/robotx-2022/catkin_ws/src/interbotix_arm/interbotix_ros_manipulators/interbotix_ros_xsarms/interbotix_xsarm_descriptions/meshes/wx200_meshes/wx200_1_base.stl</uri>
          </mesh>
        </geometry>
        <material>
          <script>
            <name>Gazebo/Black</name>
            <uri>file://media/materials/scripts/gazebo.material</uri>
          </script>
        </material>
      </visual>
      <gravity>1</gravity>
      <velocity_decay>
        <linear>0.1</linear>
        <angular>0.1</angular>
      </velocity_decay>
      <self_collide>0</self_collide>
      <enable_wind>0</enable_wind>
      <kinematic>0</kinematic>
    </link>
    <link name='wx200/shoulder_link'>
      <pose frame=''>0 0.000115 0.158 -3.14 0 0</pose>
      <inertial>
        <pose frame=''>2.2e-05 4.1e-05 0.006629 0 -0 1.5708</pose>
        <mass>0.480879</mass>
        <inertia>
          <ixx>0.000379</ixx>
          <ixy>2.2e-09</ixy>
          <ixz>-3.561e-07</ixz>
          <iyy>0.0005557</iyy>
          <iyz>1.2247e-06</iyz>
          <izz>0.0005889</izz>
        </inertia>
      </inertial>
      <collision name='wx200/shoulder_link_collision'>
        <pose frame=''>0 0 -0.003 0 -0 1.5708</pose>
        <geometry>
          <mesh>
            <scale>0.001 0.001 0.001</scale>
            <uri>/home/argrobotx/robotx-2022/catkin_ws/src/interbotix_arm/interbotix_ros_manipulators/interbotix_ros_xsarms/interbotix_xsarm_descriptions/meshes/wx200_meshes/wx200_2_shoulder.stl</uri>
          </mesh>
        </geometry>
        <max_contacts>10</max_contacts>
      </collision>
      <visual name='wx200/shoulder_link_visual'>
        <pose frame=''>0 0 -0.003 0 -0 1.5708</pose>
        <geometry>
          <mesh>
            <scale>0.001 0.001 0.001</scale>
            <uri>/home/argrobotx/robotx-2022/catkin_ws/src/interbotix_arm/interbotix_ros_manipulators/interbotix_ros_xsarms/interbotix_xsarm_descriptions/meshes/wx200_meshes/wx200_2_shoulder.stl</uri>
          </mesh>
        </geometry>
        <material>
          <script>
            <name>Gazebo/Black</name>
            <uri>file://media/materials/scripts/gazebo.material</uri>
          </script>
        </material>
      </visual>
      <gravity>1</gravity>
      <velocity_decay>
        <linear>0.1</linear>
        <angular>0.1</angular>
      </velocity_decay>
      <self_collide>0</self_collide>
      <enable_wind>0</enable_wind>
      <kinematic>0</kinematic>
    </link>
    <joint name='waist' type='revolute'>
      <child>wx200/shoulder_link</child>
      <parent>wx200/base_link</parent>
      <axis>
        <xyz>0 0 1</xyz>
        <limit>
          <lower>-3.14158</lower>
          <upper>3.14158</upper>
          <effort>8</effort>
          <velocity>3.14159</velocity>
        </limit>
        <dynamics>
          <damping>0</damping>
          <friction>0.1</friction>
          <spring_reference>0</spring_reference>
          <spring_stiffness>0</spring_stiffness>
        </dynamics>
        <use_parent_model_frame>0</use_parent_model_frame>
      </axis>
    </joint>
    <link name='wx200/upper_arm_link'>
      <pose frame=''>0 0.000176 0.11935 -3.14 0 0</pose>
      <inertial>
        <pose frame=''>0.011971 -0.000118 0.139429 0 -0 1.5708</pose>
        <mass>0.297781</mass>
        <inertia>
          <ixx>0.00171</ixx>
          <ixy>-1.1433e-06</ixy>
          <ixz>2.1161e-06</ixz>
          <iyy>0.001631</iyy>
          <iyz>0.0002135</iyz>
          <izz>0.0001482</izz>
        </inertia>
      </inertial>
      <collision name='wx200/upper_arm_link_collision'>
        <pose frame=''>0 0 0 0 -0 1.5708</pose>
        <geometry>
          <mesh>
            <scale>0.001 0.001 0.001</scale>
            <uri>/home/argrobotx/robotx-2022/catkin_ws/src/interbotix_arm/interbotix_ros_manipulators/interbotix_ros_xsarms/interbotix_xsarm_descriptions/meshes/wx200_meshes/wx200_3_upper_arm.stl</uri>
          </mesh>
        </geometry>
        <max_contacts>10</max_contacts>
      </collision>
      <visual name='wx200/upper_arm_link_visual'>
        <pose frame=''>0 0 0 0 -0 1.5708</pose>
        <geometry>
          <mesh>
            <scale>0.001 0.001 0.001</scale>
            <uri>/home/argrobotx/robotx-2022/catkin_ws/src/interbotix_arm/interbotix_ros_manipulators/interbotix_ros_xsarms/interbotix_xsarm_descriptions/meshes/wx200_meshes/wx200_3_upper_arm.stl</uri>
          </mesh>
        </geometry>
        <material>
          <script>
            <name>Gazebo/Black</name>
            <uri>file://media/materials/scripts/gazebo.material</uri>
          </script>
        </material>
      </visual>
      <gravity>1</gravity>
      <velocity_decay>
        <linear>0.1</linear>
        <angular>0.1</angular>
      </velocity_decay>
      <self_collide>0</self_collide>
      <enable_wind>0</enable_wind>
      <kinematic>0</kinematic>
    </link>
    <joint name='shoulder' type='revolute'>
      <child>wx200/upper_arm_link</child>
      <parent>wx200/shoulder_link</parent>
      <axis>
        <xyz>0 1 0</xyz>
        <limit>
          <lower>-1.88496</lower>
          <upper>1.97222</upper>
          <effort>18</effort>
          <velocity>3.14159</velocity>
        </limit>
        <dynamics>
          <damping>0</damping>
          <friction>0.1</friction>
          <spring_reference>0</spring_reference>
          <spring_stiffness>0</spring_stiffness>
        </dynamics>
        <use_parent_model_frame>0</use_parent_model_frame>
      </axis>
    </joint>
    <link name='wx200/forearm_link'>
      <pose frame=''>0.05 0.000495 -0.08065 -3.14 0 0</pose>
      <inertial>
        <pose frame=''>0.121192 -0.000124 0 0 -0 1.5708</pose>
        <mass>0.283651</mass>
        <inertia>
          <ixx>0.001185</ixx>
          <ixy>-2.4317e-06</ixy>
          <ixz>0</ixz>
          <iyy>6.829e-05</iyy>
          <iyz>0</iyz>
          <izz>0.001206</izz>
        </inertia>
      </inertial>
      <collision name='wx200/forearm_link_collision'>
        <pose frame=''>0 0 0 0 -0 1.5708</pose>
        <geometry>
          <mesh>
            <scale>0.001 0.001 0.001</scale>
            <uri>/home/argrobotx/robotx-2022/catkin_ws/src/interbotix_arm/interbotix_ros_manipulators/interbotix_ros_xsarms/interbotix_xsarm_descriptions/meshes/wx200_meshes/wx200_4_forearm.stl</uri>
          </mesh>
        </geometry>
        <max_contacts>10</max_contacts>
      </collision>
      <visual name='wx200/forearm_link_visual'>
        <pose frame=''>0 0 0 0 -0 1.5708</pose>
        <geometry>
          <mesh>
            <scale>0.001 0.001 0.001</scale>
            <uri>/home/argrobotx/robotx-2022/catkin_ws/src/interbotix_arm/interbotix_ros_manipulators/interbotix_ros_xsarms/interbotix_xsarm_descriptions/meshes/wx200_meshes/wx200_4_forearm.stl</uri>
          </mesh>
        </geometry>
        <material>
          <script>
            <name>Gazebo/Black</name>
            <uri>file://media/materials/scripts/gazebo.material</uri>
          </script>
        </material>
      </visual>
      <gravity>1</gravity>
      <velocity_decay>
        <linear>0.1</linear>
        <angular>0.1</angular>
      </velocity_decay>
      <self_collide>0</self_collide>
      <enable_wind>0</enable_wind>
      <kinematic>0</kinematic>
    </link>
    <joint name='elbow' type='revolute'>
      <child>wx200/forearm_link</child>
      <parent>wx200/upper_arm_link</parent>
      <axis>
        <xyz>0 1 0</xyz>
        <limit>
          <lower>-1.88496</lower>
          <upper>1.62316</upper>
          <effort>13</effort>
          <velocity>3.14159</velocity>
        </limit>
        <dynamics>
          <damping>0</damping>
          <friction>0.1</friction>
          <spring_reference>0</spring_reference>
          <spring_stiffness>0</spring_stiffness>
        </dynamics>
        <use_parent_model_frame>0</use_parent_model_frame>
      </axis>
    </joint>
    <link name='wx200/wrist_link'>
      <pose frame=''>0.25 0.000495 -0.08065 -3.14 0 0</pose>
      <inertial>
        <pose frame=''>0.04236 -1.1e-05 0.010577 0 -0 1.5708</pose>
        <mass>0.084957</mass>
        <inertia>
          <ixx>3.082e-05</ixx>
          <ixy>1.91e-08</ixy>
          <ixz>2.3e-09</ixz>
          <iyy>2.822e-05</iyy>
          <iyz>2.5481e-06</iyz>
          <izz>3.152e-05</izz>
        </inertia>
      </inertial>
      <collision name='wx200/wrist_link_collision'>
        <pose frame=''>0 0 0 0 -0 1.5708</pose>
        <geometry>
          <mesh>
            <scale>0.001 0.001 0.001</scale>
            <uri>/home/argrobotx/robotx-2022/catkin_ws/src/interbotix_arm/interbotix_ros_manipulators/interbotix_ros_xsarms/interbotix_xsarm_descriptions/meshes/wx200_meshes/wx200_5_wrist.stl</uri>
          </mesh>
        </geometry>
        <max_contacts>10</max_contacts>
      </collision>
      <visual name='wx200/wrist_link_visual'>
        <pose frame=''>0 0 0 0 -0 1.5708</pose>
        <geometry>
          <mesh>
            <scale>0.001 0.001 0.001</scale>
            <uri>/home/argrobotx/robotx-2022/catkin_ws/src/interbotix_arm/interbotix_ros_manipulators/interbotix_ros_xsarms/interbotix_xsarm_descriptions/meshes/wx200_meshes/wx200_5_wrist.stl</uri>
          </mesh>
        </geometry>
        <material>
          <script>
            <name>Gazebo/Black</name>
            <uri>file://media/materials/scripts/gazebo.material</uri>
          </script>
        </material>
      </visual>
      <gravity>1</gravity>
      <velocity_decay>
        <linear>0.1</linear>
        <angular>0.1</angular>
      </velocity_decay>
      <self_collide>0</self_collide>
      <enable_wind>0</enable_wind>
      <kinematic>0</kinematic>
    </link>
    <joint name='wrist_angle' type='revolute'>
      <child>wx200/wrist_link</child>
      <parent>wx200/forearm_link</parent>
      <axis>
        <xyz>0 1 0</xyz>
        <limit>
          <lower>-1.74533</lower>
          <upper>2.14675</upper>
          <effort>5</effort>
          <velocity>3.14159</velocity>
        </limit>
        <dynamics>
          <damping>0</damping>
          <friction>0.1</friction>
          <spring_reference>0</spring_reference>
          <spring_stiffness>0</spring_stiffness>
        </dynamics>
        <use_parent_model_frame>0</use_parent_model_frame>
      </axis>
    </joint>
    <link name='wx200/gripper_link'>
      <pose frame=''>0.315 0.000495 -0.08065 -3.14 0 0</pose>
      <inertial>
        <pose frame=''>0.021631 0 0.01141 0 -0 1.5708</pose>
        <mass>0.072885</mass>
        <inertia>
          <ixx>2.537e-05</ixx>
          <ixy>0</ixy>
          <ixz>0</ixz>
          <iyy>1.836e-05</iyy>
          <iyz>4.34e-07</iyz>
          <izz>1.674e-05</izz>
        </inertia>
      </inertial>
      <collision name='wx200/gripper_link_collision'>
        <pose frame=''>-0.02 0 0 0 -0 1.5708</pose>
        <geometry>
          <mesh>
            <scale>0.001 0.001 0.001</scale>
            <uri>/home/argrobotx/robotx-2022/catkin_ws/src/interbotix_arm/interbotix_ros_manipulators/interbotix_ros_xsarms/interbotix_xsarm_descriptions/meshes/wx200_meshes/wx200_6_gripper.stl</uri>
          </mesh>
        </geometry>
        <max_contacts>10</max_contacts>
      </collision>
      <visual name='wx200/gripper_link_visual'>
        <pose frame=''>-0.02 0 0 0 -0 1.5708</pose>
        <geometry>
          <mesh>
            <scale>0.001 0.001 0.001</scale>
            <uri>/home/argrobotx/robotx-2022/catkin_ws/src/interbotix_arm/interbotix_ros_manipulators/interbotix_ros_xsarms/interbotix_xsarm_descriptions/meshes/wx200_meshes/wx200_6_gripper.stl</uri>
          </mesh>
        </geometry>
        <material>
          <script>
            <name>Gazebo/Black</name>
            <uri>file://media/materials/scripts/gazebo.material</uri>
          </script>
        </material>
      </visual>
      <gravity>1</gravity>
      <velocity_decay>
        <linear>0.1</linear>
        <angular>0.1</angular>
      </velocity_decay>
      <self_collide>0</self_collide>
      <enable_wind>0</enable_wind>
      <kinematic>0</kinematic>
    </link>
    <joint name='wrist_rotate' type='revolute'>
      <child>wx200/gripper_link</child>
      <parent>wx200/wrist_link</parent>
      <axis>
        <xyz>1 0 0</xyz>
        <limit>
          <lower>-3.14158</lower>
          <upper>3.14158</upper>
          <effort>1</effort>
          <velocity>3.14159</velocity>
        </limit>
        <dynamics>
          <damping>0</damping>
          <friction>0.1</friction>
          <spring_reference>0</spring_reference>
          <spring_stiffness>0</spring_stiffness>
        </dynamics>
        <use_parent_model_frame>0</use_parent_model_frame>
      </axis>
    </joint>
    <link name='wx200/ee_arm_link'>
      <pose frame=''>0.358 0.000495 -0.08065 -3.14 0 0</pose>
      <inertial>
        <pose frame=''>0 0 0 0 -0 0</pose>
        <mass>0.001</mass>
        <inertia>
          <ixx>0.001</ixx>
          <ixy>0</ixy>
          <ixz>0</ixz>
          <iyy>0.001</iyy>
          <iyz>0</iyz>
          <izz>0.001</izz>
        </inertia>
      </inertial>
      <self_collide>0</self_collide>
      <enable_wind>0</enable_wind>
      <kinematic>0</kinematic>
    </link>
    <joint name='ee_arm' type='revolute'>
      <child>wx200/ee_arm_link</child>
      <parent>wx200/gripper_link</parent>
      <axis>
        <limit>
          <lower>0</lower>
          <upper>0</upper>
        </limit>
        <dynamics>
          <damping>0</damping>
          <friction>0</friction>
          <spring_reference>0</spring_reference>
          <spring_stiffness>0</spring_stiffness>
        </dynamics>
        <xyz>0 0 1</xyz>
        <use_parent_model_frame>0</use_parent_model_frame>
      </axis>
      <physics>
        <ode>
          <limit>
            <cfm>0</cfm>
            <erp>0.2</erp>
          </limit>
        </ode>
      </physics>
    </joint>
    <link name='wx200/gripper_prop_link'>
      <pose frame=''>0.3635 0.000495 -0.08065 -3.14 0 0</pose>
      <inertial>
        <pose frame=''>0.000846 -2e-06 4.2e-05 0 -0 1.5708</pose>
        <mass>0.00434</mass>
        <inertia>
          <ixx>5.923e-07</ixx>
          <ixy>0</ixy>
          <ixz>3.195e-07</ixz>
          <iyy>1.1156e-06</iyy>
          <iyz>-4e-10</iyz>
          <izz>5.743e-07</izz>
        </inertia>
      </inertial>
      <collision name='wx200/gripper_prop_link_collision'>
        <pose frame=''>-0.0685 0 0 0 -0 1.5708</pose>
        <geometry>
          <mesh>
            <scale>0.001 0.001 0.001</scale>
            <uri>/home/argrobotx/robotx-2022/catkin_ws/src/interbotix_arm/interbotix_ros_manipulators/interbotix_ros_xsarms/interbotix_xsarm_descriptions/meshes/wx200_meshes/wx200_7_gripper_prop.stl</uri>
          </mesh>
        </geometry>
        <max_contacts>10</max_contacts>
      </collision>
      <visual name='wx200/gripper_prop_link_visual'>
        <pose frame=''>-0.0685 0 0 0 -0 1.5708</pose>
        <geometry>
          <mesh>
            <scale>0.001 0.001 0.001</scale>
            <uri>/home/argrobotx/robotx-2022/catkin_ws/src/interbotix_arm/interbotix_ros_manipulators/interbotix_ros_xsarms/interbotix_xsarm_descriptions/meshes/wx200_meshes/wx200_7_gripper_prop.stl</uri>
          </mesh>
        </geometry>
        <material>
          <script>
            <name>Gazebo/Black</name>
            <uri>file://media/materials/scripts/gazebo.material</uri>
          </script>
        </material>
      </visual>
      <gravity>1</gravity>
      <velocity_decay>
        <linear>0.1</linear>
        <angular>0.1</angular>
      </velocity_decay>
      <self_collide>0</self_collide>
      <enable_wind>0</enable_wind>
      <kinematic>0</kinematic>
    </link>
    <joint name='gripper' type='revolute'>
      <child>wx200/gripper_prop_link</child>
      <parent>wx200/ee_arm_link</parent>
      <axis>
        <xyz>1 0 0</xyz>
        <limit>
          <lower>-1e+16</lower>
          <upper>1e+16</upper>
        </limit>
        <dynamics>
          <damping>0</damping>
          <friction>0.1</friction>
          <spring_reference>0</spring_reference>
          <spring_stiffness>0</spring_stiffness>
        </dynamics>
        <use_parent_model_frame>0</use_parent_model_frame>
      </axis>
    </joint>
    <link name='wx200/gripper_bar_link'>
      <pose frame=''>0.358 0.000495 -0.08065 -3.14 0 0</pose>
      <inertial>
        <pose frame=''>0.009687 1e-06 0.004962 0 -0 1.5708</pose>
        <mass>0.034199</mass>
        <inertia>
          <ixx>7.4125e-06</ixx>
          <ixy>-8e-10</ixy>
          <ixz>-6e-10</ixz>
          <iyy>2.843e-05</iyy>
          <iyz>-1.3889e-06</iyz>
          <izz>2.86e-05</izz>
        </inertia>
      </inertial>
      <collision name='wx200/gripper_bar_link_collision'>
        <pose frame=''>-0.063 0 0 0 -0 1.5708</pose>
        <geometry>
          <mesh>
            <scale>0.001 0.001 0.001</scale>
            <uri>/home/argrobotx/robotx-2022/catkin_ws/src/interbotix_arm/interbotix_ros_manipulators/interbotix_ros_xsarms/interbotix_xsarm_descriptions/meshes/wx200_meshes/wx200_8_gripper_bar.stl</uri>
          </mesh>
        </geometry>
        <max_contacts>10</max_contacts>
      </collision>
      <visual name='wx200/gripper_bar_link_visual'>
        <pose frame=''>-0.063 0 0 0 -0 1.5708</pose>
        <geometry>
          <mesh>
            <scale>0.001 0.001 0.001</scale>
            <uri>/home/argrobotx/robotx-2022/catkin_ws/src/interbotix_arm/interbotix_ros_manipulators/interbotix_ros_xsarms/interbotix_xsarm_descriptions/meshes/wx200_meshes/wx200_8_gripper_bar.stl</uri>
          </mesh>
        </geometry>
        <material>
          <script>
            <name>Gazebo/Black</name>
            <uri>file://media/materials/scripts/gazebo.material</uri>
          </script>
        </material>
      </visual>
      <gravity>1</gravity>
      <velocity_decay/>
      <self_collide>0</self_collide>
      <enable_wind>0</enable_wind>
      <kinematic>0</kinematic>
    </link>
    <joint name='gripper_bar' type='revolute'>
      <child>wx200/gripper_bar_link</child>
      <parent>wx200/ee_arm_link</parent>
      <axis>
        <limit>
          <lower>0</lower>
          <upper>0</upper>
        </limit>
        <dynamics>
          <damping>0</damping>
          <friction>0</friction>
          <spring_reference>0</spring_reference>
          <spring_stiffness>0</spring_stiffness>
        </dynamics>
        <xyz>0 0 1</xyz>
        <use_parent_model_frame>0</use_parent_model_frame>
      </axis>
      <physics>
        <ode>
          <limit>
            <cfm>0</cfm>
            <erp>0.2</erp>
          </limit>
        </ode>
      </physics>
    </joint>
    <link name='wx200/fingers_link'>
      <pose frame=''>0.381 0.000495 -0.08065 -3.14 0 0</pose>
      <inertial>
        <pose frame=''>0 0 0 0 -0 0</pose>
        <mass>0.001</mass>
        <inertia>
          <ixx>0.001</ixx>
          <ixy>0</ixy>
          <ixz>0</ixz>
          <iyy>0.001</iyy>
          <iyz>0</iyz>
          <izz>0.001</izz>
        </inertia>
      </inertial>
      <self_collide>0</self_collide>
      <enable_wind>0</enable_wind>
      <kinematic>0</kinematic>
    </link>
    <joint name='ee_bar' type='revolute'>
      <child>wx200/fingers_link</child>
      <parent>wx200/gripper_bar_link</parent>
      <axis>
        <limit>
          <lower>0</lower>
          <upper>0</upper>
        </limit>
        <dynamics>
          <damping>0</damping>
          <friction>0</friction>
          <spring_reference>0</spring_reference>
          <spring_stiffness>0</spring_stiffness>
        </dynamics>
        <xyz>0 0 1</xyz>
        <use_parent_model_frame>0</use_parent_model_frame>
      </axis>
      <physics>
        <ode>
          <limit>
            <cfm>0</cfm>
            <erp>0.2</erp>
          </limit>
        </ode>
      </physics>
    </joint>
    <link name='wx200/ee_gripper_link'>
      <pose frame=''>0.408575 0.000495 -0.08065 -3.14 0 0</pose>
      <inertial>
        <pose frame=''>0 0 0 0 -0 0</pose>
        <mass>0.001</mass>
        <inertia>
          <ixx>0.001</ixx>
          <ixy>0</ixy>
          <ixz>0</ixz>
          <iyy>0.001</iyy>
          <iyz>0</iyz>
          <izz>0.001</izz>
        </inertia>
      </inertial>
      <self_collide>0</self_collide>
      <enable_wind>0</enable_wind>
      <kinematic>0</kinematic>
    </link>
    <joint name='ee_gripper' type='revolute'>
      <child>wx200/ee_gripper_link</child>
      <parent>wx200/fingers_link</parent>
      <axis>
        <limit>
          <lower>0</lower>
          <upper>0</upper>
        </limit>
        <dynamics>
          <damping>0</damping>
          <friction>0</friction>
          <spring_reference>0</spring_reference>
          <spring_stiffness>0</spring_stiffness>
        </dynamics>
        <xyz>0 0 1</xyz>
        <use_parent_model_frame>0</use_parent_model_frame>
      </axis>
      <physics>
        <ode>
          <limit>
            <cfm>0</cfm>
            <erp>0.2</erp>
          </limit>
        </ode>
      </physics>
    </joint>
    <link name='wx200/left_finger_link'>
      <pose frame=''>0.381 0.000495 -0.08065 -3.14 0 0</pose>
      <inertial>
        <pose frame=''>0.013816 0 0 0 -0 -1.5708</pose>
        <mass>0.016246</mass>
        <inertia>
          <ixx>4.731e-06</ixx>
          <ixy>-4.56e-07</ixy>
          <ixz>0</ixz>
          <iyy>1.5506e-06</iyy>
          <iyz>0</iyz>
          <izz>3.7467e-06</izz>
        </inertia>
      </inertial>
      <collision name='wx200/left_finger_link_collision'>
        <pose frame=''>0 0.005 0 0 -0 3.14159</pose>
        <geometry>
          <mesh>
            <scale>0.001 0.001 0.001</scale>
            <uri>/home/argrobotx/robotx-2022/catkin_ws/src/interbotix_arm/interbotix_ros_manipulators/interbotix_ros_xsarms/interbotix_xsarm_descriptions/meshes/wx200_meshes/wx200_9_gripper_finger.stl</uri>
          </mesh>
        </geometry>
        <max_contacts>10</max_contacts>
      </collision>
      <visual name='wx200/left_finger_link_visual'>
        <pose frame=''>0 0.005 0 0 -0 3.14159</pose>
        <geometry>
          <mesh>
            <scale>0.001 0.001 0.001</scale>
            <uri>/home/argrobotx/robotx-2022/catkin_ws/src/interbotix_arm/interbotix_ros_manipulators/interbotix_ros_xsarms/interbotix_xsarm_descriptions/meshes/wx200_meshes/wx200_9_gripper_finger.stl</uri>
          </mesh>
        </geometry>
        <material>
          <script>
            <name>Gazebo/Black</name>
            <uri>file://media/materials/scripts/gazebo.material</uri>
          </script>
        </material>
      </visual>
      <gravity>1</gravity>
      <velocity_decay>
        <linear>0.1</linear>
        <angular>0.1</angular>
      </velocity_decay>
      <self_collide>0</self_collide>
      <enable_wind>0</enable_wind>
      <kinematic>0</kinematic>
    </link>
    <joint name='left_finger' type='prismatic'>
      <child>wx200/left_finger_link</child>
      <parent>wx200/fingers_link</parent>
      <axis>
        <xyz>0 1 0</xyz>
        <limit>
          <lower>0.015</lower>
          <upper>0.037</upper>
          <effort>5</effort>
          <velocity>1</velocity>
        </limit>
        <dynamics>
          <damping>0</damping>
          <friction>0.1</friction>
          <spring_reference>0</spring_reference>
          <spring_stiffness>0</spring_stiffness>
        </dynamics>
        <use_parent_model_frame>0</use_parent_model_frame>
      </axis>
    </joint>
    <link name='wx200/right_finger_link'>
      <pose frame=''>0.381 0.000495 -0.08065 -3.14 0 0</pose>
      <inertial>
        <pose frame=''>0.013816 0 0 -3.14159 -0 -1.5708</pose>
        <mass>0.016246</mass>
        <inertia>
          <ixx>4.731e-06</ixx>
          <ixy>4.56e-07</ixy>
          <ixz>0</ixz>
          <iyy>1.5506e-06</iyy>
          <iyz>0</iyz>
          <izz>3.7467e-06</izz>
        </inertia>
      </inertial>
      <collision name='wx200/right_finger_link_collision'>
        <pose frame=''>0 -0.005 0 3.14159 -0 3.14159</pose>
        <geometry>
          <mesh>
            <scale>0.001 0.001 0.001</scale>
            <uri>/home/argrobotx/robotx-2022/catkin_ws/src/interbotix_arm/interbotix_ros_manipulators/interbotix_ros_xsarms/interbotix_xsarm_descriptions/meshes/wx200_meshes/wx200_9_gripper_finger.stl</uri>
          </mesh>
        </geometry>
        <max_contacts>10</max_contacts>
      </collision>
      <visual name='wx200/right_finger_link_visual'>
        <pose frame=''>0 -0.005 0 3.14159 -0 3.14159</pose>
        <geometry>
          <mesh>
            <scale>0.001 0.001 0.001</scale>
            <uri>/home/argrobotx/robotx-2022/catkin_ws/src/interbotix_arm/interbotix_ros_manipulators/interbotix_ros_xsarms/interbotix_xsarm_descriptions/meshes/wx200_meshes/wx200_9_gripper_finger.stl</uri>
          </mesh>
        </geometry>
        <material>
          <script>
            <name>Gazebo/Black</name>
            <uri>file://media/materials/scripts/gazebo.material</uri>
          </script>
        </material>
      </visual>
      <gravity>1</gravity>
      <velocity_decay>
        <linear>0.1</linear>
        <angular>0.1</angular>
      </velocity_decay>
      <self_collide>0</self_collide>
      <enable_wind>0</enable_wind>
      <kinematic>0</kinematic>
    </link>
    <joint name='right_finger' type='prismatic'>
      <child>wx200/right_finger_link</child>
      <parent>wx200/fingers_link</parent>
      <axis>
        <xyz>0 1 0</xyz>
        <limit>
          <lower>-0.037</lower>
          <upper>-0.015</upper>
          <effort>5</effort>
          <velocity>1</velocity>
        </limit>
        <dynamics>
          <damping>0</damping>
          <friction>0.1</friction>
          <spring_reference>0</spring_reference>
          <spring_stiffness>0</spring_stiffness>
        </dynamics>
        <use_parent_model_frame>0</use_parent_model_frame>
      </axis>
    </joint>
    <static>0</static>
    <plugin name='gazebo_ros_control' filename='libgazebo_ros_control.so'>
      <robotSimType>gazebo_ros_control/DefaultRobotHWSim</robotSimType>
      <legacyModeNS>1</legacyModeNS>
      <robotNamespace>/wx200/</robotNamespace>
    </plugin>
    <plugin name='gazebo_grasp_fix' filename='libgazebo_grasp_fix.so'>
      <arm>
        <arm_name>wx200</arm_name>
        <palm_link>wx200/fingers_link</palm_link>
        <gripper_link>wx200/left_finger_link</gripper_link>
        <gripper_link>wx200/right_finger_link</gripper_link>
      </arm>
    <forces_angle_tolerance>90</forces_angle_tolerance>
    <update_rate>64</update_rate>
    <grip_count_threshold>1</grip_count_threshold>
    <max_grip_count>128</max_grip_count>
    <release_tolerance>0.0045</release_tolerance>
    <disable_collisions_on_attach>true</disable_collisions_on_attach>
    <contact_topic>__default_topic__</contact_topic>
  </plugin>

 <!-- add camera -->
  <model name="front_camera">
    <pose>0.1358 0 0.2282 0 0.19198621771 0</pose>
    <link name="link">
      <inertial>
        <pose>0.01 0.025 0.025 0 0 0</pose>
        <mass>0.01</mass>
        <inertia>
          <ixx>4.15e-6</ixx>
          <ixy>0</ixy>
          <ixz>0</ixz>
          <iyy>2.407e-6</iyy>
          <iyz>0</iyz>
          <izz>2.407e-6</izz>
        </inertia>
      </inertial>
      <sensor name="depth_camera" type="depth">
        <update_rate>30</update_rate>
        <camera>
          <horizontal_fov>1.02974</horizontal_fov>
          <image>
            <format>R8G8B8</format>
            <width>640</width>
            <height>480</height>
          </image>
          <clip>
            <near>0.1</near>
            <far>10</far>
          </clip>
        </camera>
        <plugin filename="libgazebo_ros_openni_kinect.so" name="camera_controller">
          <cameraName>drone/front_camera</cameraName>
          <alwaysOn>true</alwaysOn>
          <updateRate>30</updateRate>
          <pointCloudCutoff>0.2</pointCloudCutoff>
          <pointCloudCutoffMax>20</pointCloudCutoffMax>
          <imageTopicName>rgb/image_raw</imageTopicName>
          <cameraInfoTopicName>rgb/camera_info</cameraInfoTopicName>
          <depthImageTopicName>depth/image_raw</depthImageTopicName>
          <depthImageCameraInfoTopicName>depth/camera_info</depthImageCameraInfoTopicName>
          <pointCloudTopicName>depth/points</pointCloudTopicName>
          <frameName>drone/front_camera_optical_link</frameName>
          <distortion_k1>0.0</distortion_k1>
          <distortion_k2>0.0</distortion_k2>
          <distortion_k3>0.0</distortion_k3>
          <distortion_t1>0.0</distortion_t1>
          <distortion_t2>0.0</distortion_t2>
        </plugin>
      </sensor>
    </link>
  </model>

  <joint name="front_camera_joint" type="fixed">
    <child>front_camera::link</child>
    <parent>base_link</parent>
  </joint>

  <model name="downward45_camera">
    <pose>0.127909 0 0.187349 0 0.7853981635 0</pose>
    <link name="link">
      <inertial>
        <pose>0.01 0.025 0.025 0 0 0</pose>
        <mass>0.01</mass>
        <inertia>
          <ixx>4.15e-6</ixx>
          <ixy>0</ixy>
          <ixz>0</ixz>
          <iyy>2.407e-6</iyy>
          <iyz>0</iyz>
          <izz>2.407e-6</izz>
        </inertia>
      </inertial>

      <sensor name="depth_camera" type="depth">
        <update_rate>30</update_rate>
        <camera>
          <horizontal_fov>1.02974</horizontal_fov>
          <image>
            <format>R8G8B8</format>
            <width>640</width>
            <height>480</height>
          </image>
          <clip>
            <near>0.01</near>
            <far>10</far>
          </clip>
        </camera>
        <plugin filename="libgazebo_ros_openni_kinect.so" name="camera_controller">
          <cameraName>drone/downward_camera</cameraName>
          <alwaysOn>true</alwaysOn>
          <updateRate>60</updateRate>
          <pointCloudCutoff>0.01</pointCloudCutoff>
          <pointCloudCutoffMax>10</pointCloudCutoffMax>
          <imageTopicName>rgb/image_raw</imageTopicName>
          <cameraInfoTopicName>rgb/camera_info</cameraInfoTopicName>
          <depthImageTopicName>depth/image_raw</depthImageTopicName>
          <depthImageCameraInfoTopicName>depth/camera_info</depthImageCameraInfoTopicName>
          <pointCloudTopicName>depth/points</pointCloudTopicName>
          <frameName>drone/downward_camera_optical_link</frameName>
          <distortion_k1>0.0</distortion_k1>
          <distortion_k2>0.0</distortion_k2>
          <distortion_k3>0.0</distortion_k3>
          <distortion_t1>0.0</distortion_t1>
          <distortion_t2>0.0</distortion_t2>
        </plugin>
      </sensor>
    </link>
  </model>

  <joint name="downward_camera_joint" type="fixed">
    <child>downward45_camera::link</child>
    <parent>base_link</parent>
  </joint>

  <model name="left_camera">
    <!-- <pose>0.085811 0.092407 0.210252 0 0.192440003 1.40964135</pose> -->
    <pose>0.085811 0.092407 0.210252 0 0.192440003 0.96</pose>
    <link name="link">
      <inertial>
        <pose>0.01 0.025 0.025 0 0 0</pose>
        <mass>0.01</mass>
        <inertia>
          <ixx>4.15e-6</ixx>
          <ixy>0</ixy>
          <ixz>0</ixz>
          <iyy>2.407e-6</iyy>
          <iyz>0</iyz>
          <izz>2.407e-6</izz>
        </inertia>
      </inertial>

      <sensor name="depth_camera" type="depth">
        <update_rate>30</update_rate>
        <camera>
          <horizontal_fov>1.02974</horizontal_fov>
          <image>
            <format>R8G8B8</format>
            <width>640</width>
            <height>480</height>
          </image>
          <clip>
            <near>0.01</near>
            <far>10</far>
          </clip>
        </camera>
        <plugin filename="libgazebo_ros_openni_kinect.so" name="camera_controller">
          <cameraName>drone/left_camera</cameraName>
          <alwaysOn>true</alwaysOn>
          <updateRate>30</updateRate>
          <pointCloudCutoff>0.01</pointCloudCutoff>
          <pointCloudCutoffMax>10</pointCloudCutoffMax>
          <imageTopicName>rgb/image_raw</imageTopicName>
          <cameraInfoTopicName>rgb/camera_info</cameraInfoTopicName>
          <depthImageTopicName>depth/image_raw</depthImageTopicName>
          <depthImageCameraInfoTopicName>depth/camera_info</depthImageCameraInfoTopicName>
          <pointCloudTopicName>depth/points</pointCloudTopicName>
          <frameName>drone/left_camera_optical_link</frameName>
          <distortion_k1>0.0</distortion_k1>
          <distortion_k2>0.0</distortion_k2>
          <distortion_k3>0.0</distortion_k3>
          <distortion_t1>0.0</distortion_t1>
          <distortion_t2>0.0</distortion_t2>
        </plugin>
      </sensor>
    </link>
  </model>

  <joint name="left_camera_joint" type="fixed">
    <child>left_camera::link</child>
    <parent>base_link</parent>
  </joint>

  <model name="right_camera">
    <!-- <pose>0.085811 -0.092407 0.210252 0 0.192440003 -1.40964135</pose> -->
    <pose>0.085811 -0.092407 0.210252 0 0.192440003 -0.96</pose>
    <link name="link">
      <inertial>
        <pose>0.01 0.025 0.025 0 0 0</pose>
        <mass>0.01</mass>
        <inertia>
          <ixx>4.15e-6</ixx>
          <ixy>0</ixy>
          <ixz>0</ixz>
          <iyy>2.407e-6</iyy>
          <iyz>0</iyz>
          <izz>2.407e-6</izz>
        </inertia>
      </inertial>
      <sensor name="depth_camera" type="depth">
        <update_rate>30</update_rate>
        <camera>
          <horizontal_fov>1.02974</horizontal_fov>
          <image>
            <format>R8G8B8</format>
            <width>640</width>
            <height>480</height>
          </image>
          <clip>
            <near>0.01</near>
            <far>10</far>
          </clip>
        </camera>
        <plugin filename="libgazebo_ros_openni_kinect.so" name="camera_controller">
          <cameraName>drone/right_camera</cameraName>
          <alwaysOn>true</alwaysOn>
          <updateRate>30</updateRate>
          <pointCloudCutoff>0.01</pointCloudCutoff>
          <pointCloudCutoffMax>10</pointCloudCutoffMax>
          <imageTopicName>rgb/image_raw</imageTopicName>
          <cameraInfoTopicName>rgb/camera_info</cameraInfoTopicName>
          <depthImageTopicName>depth/image_raw</depthImageTopicName>
          <depthImageCameraInfoTopicName>depth/camera_info</depthImageCameraInfoTopicName>
          <pointCloudTopicName>depth/points</pointCloudTopicName>
          <frameName>drone/right_camera_optical_link</frameName>
          <distortion_k1>0.0</distortion_k1>
          <distortion_k2>0.0</distortion_k2>
          <distortion_k3>0.0</distortion_k3>
          <distortion_t1>0.0</distortion_t1>
          <distortion_t2>0.0</distortion_t2>
        </plugin>
      </sensor>
    </link>
  </model>

  <joint name="right_camera_joint" type="fixed">
    <child>right_camera::link</child>
    <parent>base_link</parent>
  </joint>

  </model>
</sdf>
